Workbook

Sheet Consolidat
D2: Cost reduction FRC | W2: 0 | AL2: x% | BA2: x+y% | BP2: x+z%
B3: Improvement Mng | C3: Improvement objectives per owner | D3: Cost name | E3: Comment Claudia | F3: Owner | G3: Reporting frq | H3: FRC frq | M3: 46023 | R3: 46054 | W3: 46082 | AB3: 46113 | AG3: 46143 | AL3: 46174 | AQ3: 46204 | AV3: 46235 | BA3: 46266 | BF3: 46296 | BK3: 46327 | BP3: 46357 | BU3: Total 2026
I4: Buget | J4: FRC | K4: Actual | L4: Delta Buget vs Frc | M4: FRC vs Actual | N4: Buget | O4: FRC | P4: Actual | Q4: Delta Buget vs Frc | R4: FRC vs Actual | S4: Buget | T4: FRC | U4: Actual | V4: Delta Buget vs Frc | W4: FRC vs Actual | X4: Buget | Y4: FRC | Z4: Actual | AA4: Delta Buget vs Frc | AB4: FRC vs Actual | AC4: Buget | AD4: FRC | AE4: Actual | AF4: Delta Buget vs Frc | AG4: FRC vs Actual | AH4: Buget | AI4: FRC | AJ4: Actual | AK4: Delta Buget vs Frc | AL4: FRC vs Actual | AM4: Buget | AN4: FRC | AO4: Actual | AP4: Delta Buget vs Frc | AQ4: FRC vs Actual | AR4: Buget | AS4: FRC | AT4: Actual | AU4: Delta Buget vs Frc | AV4: FRC vs Actual | AW4: Buget | AX4: FRC | AY4: Actual | AZ4: Delta Buget vs Frc | BA4: FRC vs Actual | BB4: Buget | BC4: FRC | BD4: Actual | BE4: Delta Buget vs Frc | BF4: FRC vs Actual | BG4: Buget | BH4: FRC | BI4: Actual | BJ4: Delta Buget vs Frc | BK4: FRC vs Actual | BL4: Buget | BM4: FRC | BN4: Actual | BO4: Delta Buget vs Frc | BP4: FRC vs Actual | BQ4: Buget | BR4: FRC | BS4: Actual | BT4: Delta Buget vs Frc | BU4: FRC vs Actual
D5: Revenue | E5: =1000000+250000+30000 -> 1280000
D6: White collars (fixed contracts) | F6: Lori H | G6: Q | H6: Q
D7: QHM21O
D8: QHM21O Acc Concedii
D9: QHM21R
D10: QHM21R Acc Concedii
D11: GBS
D12: Bonus QHM
D13: Subscriptie medicala
D14: GBS Acc Concedii
D16: Electricitate | F16: Vlad D | G16: M | H16: Q
D17: Eminescu 1 | H17: Q
D18: Eminescu 2
D19: Richter
D20: Onix
D21: Gaz | F21: Vlad D | G21: M | H21: Q
D22: Eminescu 1 | H22: Q
D23: Eminescu 2
D24: Richter
D25: Onix
D26: Apa | F26: Vlad D | G26: M | H26: Q
D27: Eminescu | H27: Q
D28: Richter
D29: Onix
D30: Intretinere cladiri | F30: Vlad D | G30: M | H30: Q
D31: Richter | H31: Q
D32: Onix
D33: Eminescu
D34: Horea
D35: New location | H35: Q
D36: Consumabile | F36: Amalia C | G36: BiW | H36: M
D37: Papetarie
D38: IT devices
D39: Gradinarit / Plante
D40: Produse de igiena si bucatarie
D41: Alimente (Cafea, zahar, Lapte, CO2, Ceai, Dulciuri)
D44: Combustibil | F44: Sorin C | G44: M | H44: Q
...

Sheet Outsourcing
D3: Cost reduction FRC | V3: 0 | AK3: x% | AZ3: x+y% | BO3: x+z%
B4: Improvement Mng | C4: Improvement objectives per owner | D4: Cost name | E4: Owner | F4: Reporting frq | G4: FRC frq | L4: 46023 | Q4: 46054 | V4: 46082 | AA4: 46113 | AF4: 46143 | AK4: 46174 | AP4: 46204 | AU4: 46235 | AZ4: 46266 | BE4: 46296 | BJ4: 46327 | BO4: 46357 | BT4: Total 2026
H5: Buget | I5: FRC | J5: Actual | K5: Delta Buget vs Frc | L5: FRC vs Actual | M5: Buget | N5: FRC | O5: Actual | P5: Delta Buget vs Frc | Q5: FRC vs Actual | R5: Buget | S5: FRC | T5: Actual | U5: Delta Buget vs Frc | V5: FRC vs Actual | W5: Buget | X5: FRC | Y5: Actual | Z5: Delta Buget vs Frc | AA5: FRC vs Actual | AB5: Buget | AC5: FRC | AD5: Actual | AE5: Delta Buget vs Frc | AF5: FRC vs Actual | AG5: Buget | AH5: FRC | AI5: Actual | AJ5: Delta Buget vs Frc | AK5: FRC vs Actual | AL5: Buget | AM5: FRC | AN5: Actual | AO5: Delta Buget vs Frc | AP5: FRC vs Actual | AQ5: Buget | AR5: FRC | AS5: Actual | AT5: Delta Buget vs Frc | AU5: FRC vs Actual | AV5: Buget | AW5: FRC | AX5: Actual | AY5: Delta Buget vs Frc | AZ5: FRC vs Actual | BA5: Buget | BB5: FRC | BC5: Actual | BD5: Delta Buget vs Frc | BE5: FRC vs Actual | BF5: Buget | BG5: FRC | BH5: Actual | BI5: Delta Buget vs Frc | BJ5: FRC vs Actual | BK5: Buget | BL5: FRC | BM5: Actual | BN5: Delta Buget vs Frc | BO5: FRC vs Actual | BP5: Buget | BQ5: FRC | BR5: Actual | BS5: Delta Buget vs Frc | BT5: FRC vs Actual
D6: Revenue
D7: White collars (fixed contracts) | E7: Lori H | F7: Q | G7: Q
D8: QHM21S | J8: =263704+5933+11120 -> 280757 | O8: =293734+6609+15240 -> 315583
D9: QHM21S Acc Concedii | J9: 0 | O9: 0
D10: QHM21R | J10: 0 | O10: 0
D11: QHM21R Acc Concedii | J11: 0 | O11: 0
D12: GBS | J12: 0 | O12: 0
D13: Bonus QHM | J13: 0 | O13: 0
D15: GBS Acc Concedii
D16: Electricitate | E16: Vlad D | F16: M | G16: Q
D17: Eminescu 1 | G17: Q
D18: Eminescu 2
D19: Richter
D20: Onix
D21: Gaz | E21: Vlad D | F21: M | G21: Q
D22: Eminescu 1 | G22: Q
D23: Eminescu 2
D24: Richter
D25: Onix
D26: Apa | E26: Vlad D | F26: M | G26: Q
D27: Eminescu | G27: Q
D28: Richter
D29: Onix
D30: Intretinere cladiri | E30: Vlad D | F30: M | G30: Q
D31: Richter | G31: Q
D32: Onix
D33: Eminescu
D34: Horea
D35: New location | G35: Q
D36: Consumabile | E36: Vlad D | F36: BiW | G36: M
D37: Papetarie
D38: IT devices
D39: Gradinarit / Plante
D40: Produse de igiena si bucatarie
D41: Alimente (Cafea, zahar, Lapte, CO2, Ceai, Dulciuri)
D44: Combustibil | E44: Sorin C | F44: M | G44: Q
D45: Electric | G45: Q
...

Sheet Recruitment
D3: Cost reduction FRC | W3: 0 | AL3: x% | BA3: x+y% | BP3: x+z%
B4: Improvement Mng | C4: Improvement objectives per owner | D4: Cost name | E4: Comment Claudia | F4: Owner | G4: Reporting frq | H4: FRC frq | M4: 46023 | R4: 46054 | W4: 46082 | AB4: 46113 | AG4: 46143 | AL4: 46174 | AQ4: 46204 | AV4: 46235 | BA4: 46266 | BF4: 46296 | BK4: 46327 | BP4: 46357 | BU4: Total 2026
I5: Buget | J5: FRC | K5: Actual | L5: Delta Buget vs Frc | M5: FRC vs Actual | N5: Buget | O5: FRC | P5: Actual | Q5: Delta Buget vs Frc | R5: FRC vs Actual | S5: Buget | T5: FRC | U5: Actual | V5: Delta Buget vs Frc | W5: FRC vs Actual | X5: Buget | Y5: FRC | Z5: Actual | AA5: Delta Buget vs Frc | AB5: FRC vs Actual | AC5: Buget | AD5: FRC | AE5: Actual | AF5: Delta Buget vs Frc | AG5: FRC vs Actual | AH5: Buget | AI5: FRC | AJ5: Actual | AK5: Delta Buget vs Frc | AL5: FRC vs Actual | AM5: Buget | AN5: FRC | AO5: Actual | AP5: Delta Buget vs Frc | AQ5: FRC vs Actual | AR5: Buget | AS5: FRC | AT5: Actual | AU5: Delta Buget vs Frc | AV5: FRC vs Actual | AW5: Buget | AX5: FRC | AY5: Actual | AZ5: Delta Buget vs Frc | BA5: FRC vs Actual | BB5: Buget | BC5: FRC | BD5: Actual | BE5: Delta Buget vs Frc | BF5: FRC vs Actual | BG5: Buget | BH5: FRC | BI5: Actual | BJ5: Delta Buget vs Frc | BK5: FRC vs Actual | BL5: Buget | BM5: FRC | BN5: Actual | BO5: Delta Buget vs Frc | BP5: FRC vs Actual | BQ5: Buget | BR5: FRC | BS5: Actual | BT5: Delta Buget vs Frc | BU5: FRC vs Actual
D6: Revenue
D7: White collars (fixed contracts) | F7: Lori H | G7: Q | H7: Q
D8: QHM21S
D9: QHM21S Acc Concedii
D10: QHM21R
D11: QHM21R Acc Concedii
D12: GBS
D13: Bonus QHM
D15: GBS Acc Concedii
D16: Electricitate | F16: Vlad D | G16: M | H16: Q
D17: Eminescu 1 | H17: Q
D18: Eminescu 2
D19: Richter
D20: Onix
D21: Gaz | F21: Vlad D | G21: M | H21: Q
D22: Eminescu 1 | H22: Q
D23: Eminescu 2
D24: Richter
D25: Onix
D26: Apa | F26: Vlad D | G26: M | H26: Q
D27: Eminescu | H27: Q
D28: Richter
D29: Onix
D30: Intretinere cladiri | F30: Vlad D | G30: M | H30: Q
D31: Richter | H31: Q
D32: Onix
D33: Eminescu
D34: Horea
D35: New location | H35: Q
D36: Consumabile | F36: Amalia C | G36: BiW | H36: M
D37: Papetarie
D38: IT devices
D39: Gradinarit / Plante
D40: Produse de igiena si bucatarie
D41: Alimente (Cafea, zahar, Lapte, CO2, Ceai, Dulciuri)
D44: Combustibil | F44: Sorin C | G44: M | H44: Q
D45: Electric | H45: Q
...

Sheet Coworking
D3: Cost reduction FRC | V3: 0 | AK3: x% | AZ3: x+y% | BO3: x+z%
B4: Improvement Mng | C4: Improvement objectives per owner | D4: Cost name | E4: Owner | F4: Reporting frq | G4: FRC frq | L4: 46023 | Q4: 46054 | V4: 46082 | AA4: 46113 | AF4: 46143 | AK4: 46174 | AP4: 46204 | AU4: 46235 | AZ4: 46266 | BE4: 46296 | BJ4: 46327 | BO4: 46357 | BT4: Total 2026
H5: Buget | I5: FRC | J5: Actual | K5: Delta Buget vs Frc | L5: FRC vs Actual | M5: Buget | N5: FRC | O5: Actual | P5: Delta Buget vs Frc | Q5: FRC vs Actual | R5: Buget | S5: FRC | T5: Actual | U5: Delta Buget vs Frc | V5: FRC vs Actual | W5: Buget | X5: FRC | Y5: Actual | Z5: Delta Buget vs Frc | AA5: FRC vs Actual | AB5: Buget | AC5: FRC | AD5: Actual | AE5: Delta Buget vs Frc | AF5: FRC vs Actual | AG5: Buget | AH5: FRC | AI5: Actual | AJ5: Delta Buget vs Frc | AK5: FRC vs Actual | AL5: Buget | AM5: FRC | AN5: Actual | AO5: Delta Buget vs Frc | AP5: FRC vs Actual | AQ5: Buget | AR5: FRC | AS5: Actual | AT5: Delta Buget vs Frc | AU5: FRC vs Actual | AV5: Buget | AW5: FRC | AX5: Actual | AY5: Delta Buget vs Frc | AZ5: FRC vs Actual | BA5: Buget | BB5: FRC | BC5: Actual | BD5: Delta Buget vs Frc | BE5: FRC vs Actual | BF5: Buget | BG5: FRC | BH5: Actual | BI5: Delta Buget vs Frc | BJ5: FRC vs Actual | BK5: Buget | BL5: FRC | BM5: Actual | BN5: Delta Buget vs Frc | BO5: FRC vs Actual | BP5: Buget | BQ5: FRC | BR5: Actual | BS5: Delta Buget vs Frc | BT5: FRC vs Actual
D6: Revenue
D7: White collars (fixed contracts) | E7: Lori H | F7: Q | G7: Q
D8: QHM21S
D9: QHM21S Acc Concedii
D10: QHM21R
D11: QHM21R Acc Concedii
D12: GBS
D13: Bonus QHM
D15: GBS Acc Concedii
D16: Electricitate | E16: Vlad D | F16: M | G16: Q
D17: Eminescu 1 | G17: Q
D18: Eminescu 2
D19: Richter
D20: Onix
D21: Gaz | E21: Vlad D | F21: M | G21: Q
D22: Eminescu 1 | G22: Q
D23: Eminescu 2
D24: Richter
D25: Onix
D26: Apa | E26: Vlad D | F26: M | G26: Q
D27: Eminescu | G27: Q
D28: Richter
D29: Onix
D30: Intretinere cladiri | E30: Vlad D | F30: M | G30: Q
D31: Richter | G31: Q
D32: Onix
D33: Eminescu
D34: Horea
D35: New location | G35: Q
D36: Consumabile | E36: Amalia C | F36: BiW | G36: M
D37: Papetarie
D38: IT devices
D39: Gradinarit / Plante
D40: Produse de igiena si bucatarie
D41: Alimente (Cafea, zahar, Lapte, CO2, Ceai, Dulciuri)
D44: Combustibil | E44: Sorin C | F44: M | G44: Q
D45: Electric | G45: Q
...

Sheet Calendar
A2: Open | B2: Planificare concedii
AD4: Exit speed for 2027 BG
B5: Topics | D5: March | F5: April | K5: May | O5: June | S5: July | X5: August | AB5: September | AG5: October | AK5: November | AO5: December
D6: wk12 | E6: wk13 | F6: wk14 | G6: wk15 | H6: wk16 | I6: wk17 | J6: wk18 | K6: wk19 | L6: wk20 | M6: wk21 | N6: wk22 | O6: wk23 | P6: wk24 | Q6: wk25 | R6: wk26 | S6: wk27 | T6: wk28 | U6: wk29 | V6: wk30 | W6: wk31 | X6: wk32 | Y6: wk33 | Z6: wk34 | AA6: wk35 | AB6: wk36 | AC6: wk37 | AD6: wk38 | AE6: wk39 | AF6: wk40 | AG6: wk41 | AH6: wk42 | AI6: wk43 | AJ6: wk44 | AK6: wk45 | AL6: wk46 | AM6: wk47 | AN6: wk48 | AO6: wk49 | AP6: wk50 | AQ6: wk51 | AR6: wk52
G7: Paste | AQ7: Craciun | AR7: An nou
B8: =Consolidat!D6 -> White collars (fixed contracts) | C8: =Consolidat!F6 -> Lori H | E8: BG Q3&Q4 | F8: BG Q3&Q4 | G8: Paste | H8: BG Q3&Q4 | I8: Review | J8: Review | K8: Review | AQ8: Craciun | AR8: An nou
B9: =Consolidat!D7 -> QHM21O | C9: =Consolidat!F7 -> 0 | G9: Paste | N9: FC 5+7 | R9: FC 6+6 | W9: FC7+5 | AA9: FC 8+4 | AD9: Optimizare | AE9: BG de la Client | AF9: FC 9+3 | AG9: BG 2027 | AH9: BG 2027 | AI9: BG 2027 | AJ9: FC 10+2 | AK9: BG 2027 | AL9: BG 2027 | AN9: FC 11+1 | AQ9: Craciun | AR9: An nou
B10: =Consolidat!D8 -> QHM21O Acc Concedii | C10: =Consolidat!F8 -> 0 | G10: Paste | AQ10: Craciun | AR10: An nou
B11: =Consolidat!D9 -> QHM21R | C11: =Consolidat!F9 -> 0 | G11: Paste | N11: FC 5+7 | W11: FC7+5 | AD11: Optimizare | AE11: BG estimat de Sales dep | AF11: FC 9+3 | AG11: BG 2027 | AH11: BG 2027 | AI11: BG 2027 | AJ11: BG 2027 | AK11: BG 2027 | AN11: FC 11+1 | AQ11: Craciun | AR11: An nou
B12: =Consolidat!D10 -> QHM21R Acc Concedii | C12: =Consolidat!F10 -> 0 | G12: Paste | AQ12: Craciun | AR12: An nou
B13: =Consolidat!D11 -> GBS | C13: =Consolidat!F11 -> 0 | G13: Paste | W13: FC7+5 | AD13: Optimizare | AE13: BG estimat + strategie CO | AF13: BG 2027 | AG13: BG 2027 | AH13: BG 2027 | AQ13: Craciun | AR13: An nou
B14: =Consolidat!D12 -> Bonus QHM | C14: =Consolidat!F12 -> 0 | G14: Paste | AQ14: Craciun | AR14: An nou
B15: =Consolidat!D13 -> Subscriptie medicala | C15: =Consolidat!F13 -> 0 | G15: Paste | AQ15: Craciun | AR15: An nou
B16: =Consolidat!D14 -> GBS Acc Concedii | C16: =Consolidat!F14 -> 0 | G16: Paste | AQ16: Craciun | AR16: An nou
B17: =Consolidat!D15 -> 0 | C17: =Consolidat!F15 -> 0 | G17: Paste | AQ17: Craciun | AR17: An nou
B18: =Consolidat!D16 -> Electricitate | C18: =Consolidat!F16 -> Vlad D | G18: Paste | AQ18: Craciun | AR18: An nou
B19: =Consolidat!D17 -> Eminescu 1 | C19: =Consolidat!F17 -> 0 | G19: Paste | AQ19: Craciun | AR19: An nou
B20: =Consolidat!D18 -> Eminescu 2 | C20: =Consolidat!F18 -> 0 | G20: Paste | AQ20: Craciun | AR20: An nou
B21: =Consolidat!D19 -> Richter | C21: =Consolidat!F19 -> 0 | G21: Paste | AQ21: Craciun | AR21: An nou
B22: =Consolidat!D20 -> Onix | C22: =Consolidat!F20 -> 0 | G22: Paste | AQ22: Craciun | AR22: An nou
B23: =Consolidat!D21 -> Gaz | C23: =Consolidat!F21 -> Vlad D | G23: Paste | AQ23: Craciun | AR23: An nou
B24: =Consolidat!D22 -> Eminescu 1 | C24: =Consolidat!F22 -> 0 | G24: Paste | AQ24: Craciun | AR24: An nou
B25: =Consolidat!D23 -> Eminescu 2 | C25: =Consolidat!F23 -> 0 | G25: Paste | AQ25: Craciun | AR25: An nou
... B150: =Consolidat!D148 -> Evenimente | C150: =Consolidat!F148 -> Oana C | G150: Paste | AQ150: Craciun | AR150: An nou
B151: =Consolidat!D149 -> Workshops | C151: =Consolidat!F149 -> 0 | G151: Paste
B152: =Consolidat!D150 -> Training | C152: =Consolidat!F150 -> 0 | G152: Paste
B153: =Consolidat!D151 -> Coaching | C153: =Consolidat!F151 -> 0 | G153: Paste
B154: =Consolidat!D152 -> 0 | C154: =Consolidat!F152 -> 0 | G154: Paste
B155: =Consolidat!D153 -> Fixed Conv. Subtotal | C155: =Consolidat!F153 -> 0 | G155: Paste
